Traceback (most recent call last):
  File "/nobackup/ml14je/Packages/baroclinicSWEs/baroclinicSWEs/Analyses/Model B/parameter_runs.py", line 355, in parameter_run
    energies[(param.alpha, param.beta)]
KeyError: (0.1, 0.14)

During handling of the above exception, another exception occurred:

Traceback (most recent call last):
  File "/nobackup/ml14je/Packages/baroclinicSWEs/baroclinicSWEs/Analyses/solutions.py", line 71, in barotropic_flow
    with open(sln_dir, "rb") as inp:
FileNotFoundError: [Errno 2] No such file or directory: 'Barotropic/Functions/Domain=1300kmx1300km_OceanDepth=4000m_ShelfDepth=200m_ShelfWidth=100km_SlopeWidth=50km_CanyonWidth=20.0km_alpha=0.10_beta=0.14_domainpadding=350km_dampingwidth=150km_N=3.pkl'

During handling of the above exception, another exception occurred:

Traceback (most recent call last):
  File "/nobackup/ml14je/Packages/baroclinicSWEs/baroclinicSWEs/Analyses/Model B/parameter_runs.py", line 463, in <module>
    parameter_run(
  File "/nobackup/ml14je/Packages/baroclinicSWEs/baroclinicSWEs/Analyses/Model B/parameter_runs.py", line 358, in parameter_run
    barotropic_solution, baroclinic_solution = startup(
  File "/nobackup/ml14je/Packages/baroclinicSWEs/baroclinicSWEs/Analyses/Model B/parameter_runs.py", line 145, in startup
    solutions.barotropic_flow(
  File "/nobackup/ml14je/Packages/baroclinicSWEs/baroclinicSWEs/Analyses/solutions.py", line 83, in barotropic_flow
    u_kelv, v_kelv, p_kelv, ω, k = kelvin_solver(
  File "/nobackup/ml14je/Packages/barotropicSWEs/barotropicSWEs/SWEs.py", line 392, in kelvin_solver
    with open(f"{foldername}/{filename}", "wb") as f:
FileNotFoundError: [Errno 2] No such file or directory: 'Barotropic/Kelvin Flow/OceanDepth=4000m_ShelfDepth=200m_ShelfWidth=100km_SlopeWidth=50km_CanyonWidth=20.0km_alpha=0.10_beta=0.14_domainpadding=350km/KelvinMode_Domain=200kmx200km_ω=1.4e-04_ω=1.4.pkl'
